<?xml version="1.0"?>
<robot name="armaan_robo" xmlns:xacro="http://www.ros.org/wiki/xacro">

    <xacro:property name="pi_const" value="3.14159265"/>

    <xacro:property name="a" value="1"/>
    <xacro:property name="b" value="0.3"/>
    <xacro:property name="c" value="0.6"/>

    <xacro:property name="r" value="0.15"/>
    <xacro:property name="d" value="0.1"/>

    <xacro:property name="s1" value="${b/2+r}" />
    <xacro:property name="s2" value="${2*r}" />
    <xacro:property name="s3" value="${2*r}" />
    <xacro:property name="s4" value="${c/2+d/2}" />

    <xacro:property name="d1" value="2710.0"/>
    <xacro:property name="d2" value="2710.0"/>
    <xacro:property name="d3" value="2710.0"/>

    <xacro:property name="m1" value="${d1*a*b*c}"/>
    <xacro:property name="m2" value="${d2*pi_const*r*r*d}"/>
    <xacro:property name="m3" value="${d3*(4.0/3.0)*pi_const*r*r*r}"/>

    <xacro:property name="Ix_body" value="${(1/12)*m1*(b*b+c*c)}" />
    <xacro:property name="Iy_body" value="${(1/12)*m1*(a*a+b*b)}" />
    <xacro:property name="Iz_body" value="${(1/12)*m1*(a*a+c*c)}" />

    <xacro:property name="Iz_wheel" value="${0.5*m2*r*r}" />
    <xacro:property name="I_wheel" value="${(1.0/12.0)*m2*(3.0*r*r+d*d)}"/>

    <xacro:property name="I_caster" value="${(2.0/5.0)*m3*r*r}" />

    <xacro:macro name="inertia_body">
        <inertial>
            <origin rpy="0 0 0" xyz="0 0 0"/>
            <mass value="${m1}"/>
            <inertia ixx="${Ix_body}" ixy="0.0" ixz="0.0" iyy="${Iy_body}" iyz="0.0" izz="${Iz_body}" />
        </inertial>
    </xacro:macro>

    <xacro:macro name="inertia_wheel">
        <inertial>
            <origin rpy="1.570795 0 0" xyz="0 0 0" />
            <mass value="${m2}"/>
            <inertia ixx="${I_wheel}" ixy="0.0" ixz="0.0" iyy="${I_wheel}" iyz="0.0" izz="${Iz_wheel}" />
        </inertial>
    </xacro:macro>

    <xacro:macro name="inertia_caster">
        <inertial>
            <origin rpy="0 0 0" xyz="0 0 0"/>
            <mass value="${m3}" />
            <inertia ixx="${I_caster}" ixy="0.0" ixz="0.0" iyy="${I_caster}" iyz="0.0" izz="${I_caster}" />
        </inertial>
    </xacro:macro>

    <link name="base_fixx"></link>

    <joint name="body_joint" type="fixed">
        <parent link="base_fixx"/>
        <child link="box_link"/>
        <origin xyz="0 0 ${s1}" rpy="0 0 0"/>
    </joint>

    <xacro:include filename="$(find arma_rob)/model/armrob.gazebo"/>

    <link name="box_link">
        <visual>
            <origin rpy="0 0 0" xyz="0 0 0" />
            <geometry>
                <box size="${a} ${c} ${b}"/>
            </geometry>
        </visual>

        <collision>
            <origin rpy="0 0 0" xyz="0 0 0" />
            <geometry>
                <box size="${a} ${c} ${b}"/>
            </geometry>
        </collision>
            
        <xacro:inertia_body />
    </link> 

    <joint name="wheel_joint" type="continuous">
        <parent link="box_link" />
        <child link="1wheel_link" />
        <origin xyz="${-s2} ${-s4} ${-b/2}" rpy="0 0 0" />
        <axis xyz="0 1 0" />
        <limit effort="50000" velocity="10"/>
        <dynamics damping="1.0" friction="3.0"/>
    </joint>

    <link name="1wheel_link">
        <visual>
            <origin rpy="1.570795 0 0" xyz="0 0 0"/>
            <geometry>
                <cylinder length="${d}" radius="${r}"/>
            </geometry>
        </visual>

        <collision>
            <origin rpy="1.570795 0 0" xyz="0 0 0" />
            <geometry>
                <cylinder length="${d}" radius="${r}"/>
            </geometry>
        </collision>

        <xacro:inertia_wheel />
    </link>  

    <joint name="2wheel_joint" type="continuous">
        <parent link="box_link"/>
        <child link="2wheel_link"/>
        <origin xyz="${-s2} ${s4} ${-b/2}" rpy="0 0 0 " />
        <axis xyz="0 1 0" />
        <limit effort="50000" velocity="10" />
        <dynamics damping="1.0" friction="3.0"/>
    </joint>

    <link name="2wheel_link">
        <visual>
            <origin rpy="1.570795 0 0" xyz="0 0 0"/>
            <geometry>
                <cylinder length="${d}" radius="${r}"/>
            </geometry>
        </visual>

        <collision>
            <origin rpy="1.570795 0 0" xyz="0 0 0"/>
            <geometry>
                <cylinder length="${d}" radius="${r}"/>
            </geometry> 
        </collision>

        <xacro:inertia_wheel/>
    </link>

    <joint name="caster_joint" type="fixed">
        <parent link="box_link"/>
        <child link="caster_link"/>
        <origin xyz="${s3} 0 ${-b/2}" rpy="0 0 0"/>
    </joint>

    <link name="caster_link">
        <visual>
            <origin rpy="0 0 0" xyz="0 0 0"/>
            <geometry>
                <sphere radius="${r}" />
            </geometry>
        </visual>

        <collision>
            <origin rpy="0 0 0" xyz= "0 0 0 "/>
            <geometry>
                <sphere radius="${r}" />
            </geometry>
        </collision>
        <xacro:inertia_caster />
    </link>

</robot>
